<!-- 底盘添加摄像头 -->
<robot name = "mycar" >
    <!-- 底盘link -->
    <link name = "base_link" >
        <visual>
            <geometry>
                <box size = "0.3 0.2 0.1" />
            </geometry>
            <origin xyz = "0 0 0" rpy = "0 0 0" />
            <material name = "car_color">
                <color rgba = "0.5 0.5 0.5 0.7" />
            </material>
        </visual>
    </link>
    <!-- 摄像头link -->
    <link name = "camera" >
        <visual>
            <geometry>
                <box size = "0.02 0.05 0.05" />
            </geometry>
            <origin xyz = "0 0 0.025" rpy = "0 0 0" />
            <material name = "camera_color">
                <color rgba = "0 0.5 0 0.7" />
            </material>
        </visual>
    </link>
    <!-- 关节 -->
    <!-- continuous 旋转关节(无限) fixed 固定关节 -->
    <joint name = "camera2base" type = "continuous" >
        <!-- 父级 link -->
        <parent link = "base_link" />
        <!-- 子级 link -->
        <child link = "camera" />
        <!-- 偏移量 -->
        <origin xyz = "0.12 0 0.05" rpy = "0 0 0" />
        <!-- 旋转参考轴 -->
        <axis xyz = "0 0 1" />
    </joint>
</robot >